def pytest_configure():
    from django.conf import settings

    settings.configure(
        DEBUG_PROPAGATE_EXCEPTIONS=True,
        DATABASES={
            'default': {
                'ENGINE': 'django.db.backends.sqlite3',
                'NAME': ':memory:'
            }
        },
        SITE_ID=1,
        SECRET_KEY='not very secret in tests',
        USE_I18N=True,
        STATIC_URL='/static/',
        ROOT_URLCONF='tests.urls',
        TEMPLATES=[
            {
                'BACKEND': 'django.template.backends.django.DjangoTemplates',
                'APP_DIRS': True,
            },
        ],
        MIDDLEWARE=(
            'django.contrib.sessions.middleware.SessionMiddleware',
            'django.middleware.common.CommonMiddleware',
            'django.contrib.auth.middleware.AuthenticationMiddleware',
            'django.contrib.messages.middleware.MessageMiddleware',
        ),
        INSTALLED_APPS=(
            'django.contrib.auth',
            'django.contrib.contenttypes',
            'django.contrib.sessions',
            'django.contrib.sites',
            'django.contrib.staticfiles',
            'rest_framework',
            'knox',
            'tests',
        ),
        PASSWORD_HASHERS=(
            'django.contrib.auth.hashers.MD5PasswordHasher',
        ),
        REST_FRAMEWORK={
            'DEFAULT_AUTHENTICATION_CLASSES': [
                'rest_framework.authentication.BasicAuthentication',
                'rest_framework.authentication.SessionAuthentication',
            ],
        },
    )

    try:
        import django
        django.setup()
    except AttributeError:
        pass
